Workbook

Sheet 2026 Bid Tracker
A1: Job ID | B1: Month | C1: Client | D1: Project Name | E1: Bid Due Date | F1: Drawing Stage | G1: Bid Type | H1: Sent Date | I1: Sub. Method | J1: Status | K1: Win? | L1: Job Type | M1: Est. Bid Value | N1: Link: Drawings | O1: Link: Specs | P1: Link: Schedule | Q1: Notes | R1: Bid Feedback | S1: NTP Received? | T1: Final Cost | U1: Profit Margin ($) | V1: CO Link | W1: Lessons Learned
B2: January
A3: Q-26-003 | C3: Viking | D3: Legacy Good Sam Pharmacy Retrofit | E3: 46038 | F3: CD | G3: Hard Bid | H3: 01/16/2026 | I3: Email | J3: Won | K3: =IF(J3="Won","✔","") -> ✔ | M3: 47988
A4: Q-26-004 | C4: Brian Kasler | D4: Ktichen & Bath Cabinets | E4: 46041 | F4: Email | G4: Budget | H4: 01/19/2026 | I4: Email | J4: Sent | K4: =IF(J4="Won","✔","") | L4: Residential | M4: 58551
A5: Q-26-005 | C5: Schommer & Sons | D5: Tualatin Park Office Reno | E5: 46044 | F5: Bid Set | G5: Hard Bid | H5: 01/22/2026 | I5: BuildingConnected | J5: Sent | K5: =IF(J5="Won","✔","") | L5: Renovation | M5: 9481
A6: Q-26-006 | C6: Ross Builder | D6: Tualatin Park Office Reno | E6: 46044 | F6: Bid Set | G6: Hard Bid | H6: 01/22/2026 | I6: BuildingConnected | J6: Sent | K6: =IF(J6="Won","✔","") | L6: Renovation | M6: 9481
A7: Q-26-007 | C7: Legacy Salmon Creek | D7: 527 Closet Cab | E7: 46038 | F7: Email | G7: Hard Bid | H7: 01/16/2026 | I7: Email | J7: Sent | K7: =IF(J7="Won","✔","") | L7: Healthcare | M7: 1052
A8: Q-26-008 | C8: Norwest | D8: Gresham Advanced Dentistry | E8: 46034 | F8: Email | G8: Budget | H8: 01/14/2026 | I8: Email | J8: Sent | K8: =IF(J8="Won","✔","") | L8: Dental | M8: 6150
A9: Q-26-009 | C9: Tim- TRBLDG Servies | D9: NW Primary Care- SE Mallard Way | E9: 46036 | F9: Email | G9: Hard Bid | H9: 01/14/2026 | I9: Email | J9: Won | K9: =IF(J9="Won","✔","") -> ✔ | M9: 1900
A10: Q-26-010 | C10: Manion Design | D10: Back Bar Cabs | E10: 46037 | F10: Email | G10: Hard Bid | I10: Email | J10: Won | K10: =IF(J10="Won","✔","") -> ✔ | M10: 2325
A11: Q-26-011 | C11: OHSU HMC | D11: 8th Ave Ste 205 | E11: 46038 | F11: Email | G11: Hard Bid | H11: 01/16/2026 | I11: Email | J11: Sent | K11: =IF(J11="Won","✔","") | L11: Healthcare | M11: 1147
A12: Q-26-012 | C12: OHSU HMC | D12: Rm 1321 Countertop | E12: 46037 | F12: Email | G12: Hard Bid | I12: Email | J12: Won | K12: =IF(J12="Won","✔","") -> ✔ | L12: Healthcare | M12: 1180
A13: Q-26-013 | C13: Idea Interiors | D13: Coats & Tails Lobby Remodel | E13: 46036 | F13: Email | G13: Hard Bid | I13: Email | J13: Won | K13: =IF(J13="Won","✔","") -> ✔ | L13: Commercial TI | M13: 3920
A14: Q-26-014 | C14: Five Star | D14: Meridian Park FSB- Corian CT | E14: 46036 | F14: Email | G14: Hard Bid | H14: 01/14/2026 | I14: Email | J14: Sent | K14: =IF(J14="Won","✔","") | M14: 7218
A15: Q-26-015 | C15: Five Star | D15: Systems Cabinets | E15: 46037 | F15: Email | I15: Email | J15: Sent | K15: =IF(J15="Won","✔","") | M15: 35919
A16: Q-26-016 | C16: Five Star | D16: Emanuel Rm 1611 | E16: 46037 | F16: Email | G16: Hard Bid | H16: 01/14/2026 | I16: Email | J16: Won | K16: =IF(J16="Won","✔","") -> ✔ | L16: Healthcare | M16: 5713
A17: Q-26-017 | B17: On Hold | C17: Wilammette Falls | D17: Behavioral Sloped Corian | J17: On Hold | K17: =IF(J17="Won","✔","")
A18: Q-26-018 | C18: Wilammette Falls | D18: ICU Corian CT | E18: 46037 | F18: Email | G18: Hard Bid | H18: 01/15/2026 | I18: Email | J18: Sent | K18: =IF(J18="Won","✔","") | L18: Hospital | M18: 3715
A19: Q-26-019 | C19: Wilammette Falls | D19: 17 Cab Drawers w/ servo drive | E19: 46037 | F19: Email | G19: Hard Bid | I19: Email | J19: Sent | K19: =IF(J19="Won","✔","") | L19: Hospital | M19: 9930
A20: Q-26-020 | C20: VAM | D20: Aligned Hillsboro Campus | E20: 46037 | F20: Email | G20: Hard Bid | I20: Email | J20: Won | K20: =IF(J20="Won","✔","") -> ✔ | L20: Commercial | M20: 3622
A21: Q-26-021 | C21: Norwest | D21: Stones Dental- Added Scope/ Sterile Revision | K21: =IF(J21="Won","✔","")
A22: Q-26-022 | C22: Trainor | D22: Herman Miller Wood Ceiling Install | E22: 46043 | F22: Email | G22: Hard Bid | H22: 01/21/2026 | I22: Email | J22: Sent | K22: =IF(J22="Won","✔","") | L22: Commercial | M22: 25800
A23: Q-26-023 | C23: Trainor | D23: Design Within Reach | E23: 46043 | F23: Email | G23: Hard Bid | H23: 01/21/2026 | I23: Email | J23: Sent | K23: =IF(J23="Won","✔","") | L23: Commercial
A24: Q-26-024 | C24: Robert Hakes | D24: Elite Recovery | E24: 46044 | F24: Email | G24: Hard Bid | K24: =IF(J24="Won","✔","") | M24: 3350
A25: Q-26-025 | C25: Essex | D25: Bonneville St Johns | E25: 46041 | F25: Email | G25: Hard Bid | H25: 46023 | I25: Email | J25: Won | K25: =IF(J25="Won","✔","") -> ✔ | M25: 3845
A26: Q-26-026 | C26: Andersen | D26: Meadowlark Place | E26: 46045 | F26: Email | G26: Hard Bid | H26: 01/23/2026 | I26: Email | J26: Sent | K26: =IF(J26="Won","✔","") | L26: Healthcare | M26: 89846
A27: Q-26-027 | C27: LMC | D27: Meadowlark Place | E27: 46049 | F27: Bid Set | G27: Hard Bid | H27: 01/23/2026 | I27: BuildingConnected | J27: Sent | K27: =IF(J27="Won","✔","") | L27: Healthcare | M27: 89846
A28: Q-26-028 | C28: Viking | D28: Legacy GS WHA Expansion | E28: 46042 | F28: Bid Set | G28: Hard Bid | H28: 01/20/2026 | I28: Email | J28: Sent | K28: =IF(J28="Won","✔","") | L28: Healthcare | M28: 86074
A29: Q-26-029 | C29: Viking | D29: Legacy EMC Trauma Relocation | E29: 46042 | F29: 50% SD | G29: Budget | H29: 01/20/2026 | I29: Email | J29: Sent | K29: =IF(J29="Won","✔","") | L29: Healthcare, Renovation | M29: 65183
A30: Q-26-030 | C30: Cameron's Chok Dee | D30: Pacific Towers Ste 1012 Revised Layout | E30: 46042 | F30: Bid Set | G30: Hard Bid | H30: 01/20/2026 | I30: Email | J30: Won | K30: =IF(J30="Won","✔","") -> ✔ | L30: Commercial | M30: 9290
A31: Q-26-031 | C31: CCDC | D31: 153 Volcano View- Cam's Casework | E31: 46049 | F31: Email | G31: Design Assist | H31: 02/06/2026 | I31: Email | J31: Sent | K31: =IF(J31="Won","✔","") | M31: 4114
A32: Q-26-032 | C32: Inline | D32: Pacific University Dining Cabs & CT | E32: 46044 | F32: Email | G32: Hard Bid | H32: 01/22/2026 | I32: Email | J32: Sent | K32: =IF(J32="Won","✔","") | M32: 5125
A33: Q-26-033 | C33: Design Build | D33: NW Urology Price 3 base Cabs | E33: 46048 | F33: Email | H33: 01/26/2026 | I33: Email | J33: Sent | K33: =IF(J33="Won","✔","") | L33: Healthcare | M33: 1430
A34: Q-26-034 | C34: Five Star | D34: Legacy Silverton Purple Casework | E34: 46048 | F34: Email | G34: Hard Bid | H34: 01/26/2026 | I34: Email | J34: Sent | K34: =IF(J34="Won","✔","") | L34: Healthcare, Renovation | M34: 4726
A35: Q-26-035 | C35: Trainor Construction | D35: Design Within Reach | E35: 46037 | F35: Email | G35: Hard Bid | H35: 01/15/2026 | I35: Email | J35: Won | K35: =IF(J35="Won","✔","") -> ✔ | L35: TI, Commercial | M35: 22923
B36: February
A37: Q-26-037 | C37: Norwest | D37: Clemons Oral Surgery | E37: 46055 | F37: Email | G37: Hard Bid | H37: 02/02/2026 | I37: Procore | J37: Client Lost | K37: =IF(J37="Won","✔","") | L37: Dental | M37: 102519 | Q37: We beat Gunderson
A38: Q-26-038 | B38: 01/22/2026 | C38: Norwest | D38: Legacy TOC OBGYN Expansion | E38: 46055 | F38: 100% DD | G38: Hard Bid | H38: 02/02/2026 | I38: Procore | J38: Sent | K38: =IF(J38="Won","✔","") | L38: Healthcare, TI | M38: 91705
A39: Q-26-039 | C39: Viking | D39: Legacy TOC OBGYN Expansion | E39: 46057 | F39: 100% DD | G39: Hard Bid | H39: 02/02/2026 | I39: Email | J39: Sent | K39: =IF(J39="Won","✔","") | L39: Healthcare, TI | M39: 99349
A40: Q-26-040 | C40: Five Star | D40: Legacy TOC OBGYN Expansion | E40: 46058 | F40: 100% DD | G40: Hard Bid | H40: 02/02/2026 | I40: Email | J40: Sent | K40: =IF(J40="Won","✔","") | L40: Healthcare, TI | M40: 99349
...

Sheet 2025 Bid Tracker
A1: Job ID | B1: Month | C1: Client | D1: Project Name | E1: Bid Due Date | F1: Drawing Stage | G1: Bid Type | H1: Sent Date | I1: Sub. Method | J1: Status | K1: Win? | L1: Job Type | M1: Est. Bid Value | N1: Link: Drawings | O1: Link: Specs | P1: Link: Schedule | Q1: Notes | R1: Bid Feedback | S1: NTP Received? | T1: Final Cost | U1: Profit Margin ($) | V1: CO Link | W1: Lessons Learned
B2: May
A3: Q-25-003 | C3: Ross | D3: Forest Grove HS Renovations | E3: 05/15/2025 | F3: Bid Set | G3: Hard Bid | H3: 05/15/2025 | I3: Email | J3: Sent | K3: =IF(J3="Won","✔","") | L3: School | M3: 53368
A4: Q-25-004 | C4: Andersen | D4: UO Acoustic Research Lab | E4: 05/21/2015 | F4: Bid Set | G4: Hard Bid | H4: 05/21/2015 | I4: Email | J4: Sent | K4: =IF(J4="Won","✔","") | L4: School | M4: 19226
A5: Q-25-005 | C5: Robert Hakes | D5: Coldwell Banker Bain Lake Oswego | E5: 05/14/2025 | G5: Design Assist | H5: 05/14/2025 | I5: Email | J5: Sent | K5: =IF(J5="Won","✔","") | L5: TI | M5: Opt #1 $7649 / Opt #2 5367
A6: Q-25-006 | C6: Norwest | D6: ZoomCare Progress Ridge | E6: 05/16/2025 | G6: Hard Bid | H6: 05/16/2025 | I6: Email | J6: Sent | K6: =IF(J6="Won","✔","") | L6: Healthcare, TI | M6: 22134
A7: Q-25-007 | C7: Cornice | D7: Harmony BLD1 & 2- Spec TI | E7: 05/23/2025 | G7: Hard Bid | H7: 05/23/2025 | I7: Email | J7: Client Lost | K7: =IF(J7="Won","✔","") | M7: 6984 | R7: $1000 high | S7: No
A8: Q-25-008 | C8: Robert Hakes | D8: Therapeutic Associates 3 Room | E8: 05/15/2025 | G8: Budget | H8: 05/15/2025 | I8: Email | J8: Sent | K8: =IF(J8="Won","✔","") | L8: Healthcare, TI | M8: 18814 | Q8: Sent Budget for Qtz (quod minui) & P-lam Deduct 5.15.25
A9: Q-25-009 | C9: Lease Crutcher Lewis | D9: Legacy Salmon Creek CT Replacement | E9: 05/29/2025 | G9: Budget | H9: 05/29/2025 | I9: Email | J9: Sent | K9: =IF(J9="Won","✔","") | L9: Healthcare, Hospital | M9: 8329
B10: June
A11: Q-25-011 | C11: Lease Crutcher Lewis | D11: PeaceHealth CMP Urology Renovation | E11: 06/24/2024 | F11: CD | G11: Hard Bid | H11: 06/04/2025 | I11: Email | J11: Declined | K11: =IF(J11="Won","✔","") | L11: Healthcare, Renovation | M11: 100268 | N11: https://www.zztakeoff.com/app/takeoff?projectId=GamthffsBwLTgtDHo&pageId=iSohJaS4iSpkATZRJ , https://mylewis-my.sharepoint.com/personal/kagan_reardon_lewisbuilds_com/_layouts/15/onedrive.aspx?id=%2Fpersonal%2Fkagan%5Freardon%5Flewisbuilds%5Fcom%2FDocuments%2FDocuments%2F%5FPC25029%20%2D%20PEAC%20CMP%20UROLOGY%2FPC25029%20PEAC%20CMP%20UROLOGY%20%2D%20Drawings&ga=1 | Q11: Alt Accepted | S11: Yes
A12: Q-25-012 | C12: Howard S Wright | D12: Kaiser IRT HDR & CT Procedure Suite Expansion | E12: 06/02/2024 | H12: 06/02/2025 | I12: Email | J12: Sent | K12: =IF(J12="Won","✔","") | L12: Healthcare, Hospital | M12: 64694.8
A13: Q-25-013 | C13: Andersen | D13: Legacy Emanuel Apothecary | E13: 06/04/2025 | G13: Budget | H13: 06/04/2025 | J13: Sent | K13: =IF(J13="Won","✔","") | L13: Healthcare | M13: 49667
A14: Q-25-014 | C14: Norwest | D14: Willowbrook Vet | E14: 06/10/2025 | F14: Bid Set | G14: Hard Bid | H14: 06/10/2025 | I14: Procore | J14: On Hold | K14: =IF(J14="Won","✔","") | L14: Vet | M14: 27990
A15: Q-25-015 | C15: Robert Hakes | D15: Beem Light Sauna- Install Only | E15: 06/02/2025 | F15: Permit | G15: Install Only | H15: 06/02/2025 | I15: Email | J15: Won | K15: =IF(J15="Won","✔","") -> ✔ | L15: TI, Healthcare | M15: 895 | P15: 09/19/2025 | S15: Yes
A16: Q-25-016 | C16: Schaffran | D16: PPMC Restroom Counters | E16: 06/01/2025 | H16: 06/01/2025 | J16: Sent | K16: =IF(J16="Won","✔","") | M16: 6724.76
A17: Q-25-017 | C17: Schaffran | D17: PPMC Day Room Ice Machine | E17: 06/01/2025 | H17: 06/01/2025 | J17: Sent | K17: =IF(J17="Won","✔","") | M17: 496
A18: Q-25-018 | C18: Schaffran | D18: PPMC Control Room Desk | E18: 06/02/2025 | H18: 06/02/2025 | J18: Sent | K18: =IF(J18="Won","✔","") | M18: 5330
A19: Q-25-019 | C19: Lease Crutcher Lewis | D19: Legacy Salmon Creek MOB 2-Cardio | E19: 06/27/2025 | H19: 06/27/2025 | I19: BuildingConnected | J19: Sent | K19: =IF(J19="Won","✔","") | M19: 90865 | N19: https://app.buildingconnected.com/opportunities/683a24fe1ed47200532f624c/files
A20: Q-25-020 | C20: Cameron Chok-Dee | D20: Oregon State Bar | E20: 06/06/2025 | H20: 06/06/2025 | J20: Sent | K20: =IF(J20="Won","✔","") | M20: 21178
A21: Q-25-021 | C21: Cameron Chok-Dee | D21: Pacific BLDG TI | E21: 06/06/2025 | F21: Bid Set | G21: Hard Bid | H21: 06/06/2002 | J21: Sent | K21: =IF(J21="Won","✔","") | M21: 6886
A22: Q-25-022 | C22: Andersen | D22: TV Camas- Phase 2 Budget | E22: 06/17/2025 | F22: 100% DD | G22: Budget | H22: 06/17/2025 | I22: BuildingConnected | J22: Sent | K22: =IF(J22="Won","✔","") | M22: 371276
A23: Q-25-023 | C23: LSCMC | D23: Family Birth Suite 407 | E23: 06/18/2025 | F23: Bid Set | G23: Hard Bid | H23: 06/18/2025 | I23: Email | J23: Won | K23: =IF(J23="Won","✔","") -> ✔ | L23: Hospital, Renovation | M23: 16486 | P23: Install 8/27/25
A24: Q-25-024 | C24: Essex | D24: NWN PLNG Cabinets | E24: 06/09/2025 | H24: 06/09/2025 | J24: Won | K24: =IF(J24="Won","✔","") -> ✔ | M24: 5443 | S24: Yes
A25: Q-25-025 | C25: Andersen | D25: Providence PPP Ste 118 | E25: 06/25/2025 | F25: 50% SD | G25: Budget | H25: 06/25/2025 | K25: =IF(J25="Won","✔","") | M25: 54168
A26: Q-25-026 | C26: Andersen | D26: HMC Cath Lab 2 | E26: 06/19/2025 | F26: Bid Set | G26: Hard Bid | H26: 06/26/2025 | I26: Email | J26: Won | K26: =IF(J26="Won","✔","") -> ✔ | L26: Hospital, Renovation | M26: 11862 | S26: Yes
A27: Q-25-027 | C27: Schaffran | D27: OHSU School of Nursing 550 Classroom | E27: 06/20/2025 | F27: 50% SD | G27: Budget | H27: 06/20/2025 | K27: =IF(J27="Won","✔","") | M27: 37713
A28: Q-25-028 | C28: Norwest | D28: Archie's Playground | E28: 06/25/2025 | H28: 06/25/2025 | K28: =IF(J28="Won","✔","") | M28: 59333
B29: July
A30: Q-25-030 | B30: 06/27/2025 | C30: Built Environments NW | D30: Elephant's Deli-Supply/Install CT | E30: 07/02/2015 | F30: Bid Set | G30: Hard Bid | H30: 07/03/2025 | I30: Email | J30: Client Lost | K30: =IF(J30="Won","✔","") | L30: Commercial, TI | M30: 1180
A31: Q-25-031 | B31: 07/03/2025 | C31: Pacific Premier Group | D31: Fix and Move Reception Desk | E31: 07/03/2025 | F31: Bid Set | G31: Hard Bid | H31: 07/09/2025 | I31: Email | J31: Sent | K31: =IF(J31="Won","✔","") | L31: Healthcare, Renovation | M31: 1671
A32: Q-25-032 | B32: 07/01/2025 | C32: Bremik | D32: Eagle Industrial Equip. Warehouse | E32: 07/09/2025 | F32: Bid Set | G32: Hard Bid | H32: 07/07/2025 | I32: Other | J32: Sent | K32: =IF(J32="Won","✔","") | L32: Commercial | M32: 14205
A33: Q-25-033 | B33: 07/02/2025 | C33: Centrex | D33: Hangar Golf West Kitchen TI | E33: 07/09/2025 | F33: Bid Set | G33: Hard Bid | H33: 06/24/2025 | I33: Email | J33: Sent | K33: =IF(J33="Won","✔","") | L33: Commercial | M33: 15928 | R33: 8/7 Follow up- Waiting on Client approval
A34: Q-25-034 | B34: 07/02/2025 | C34: Centrex | D34: Hangar Golf West RR TI | E34: 07/09/2025 | F34: Bid Set | G34: Hard Bid | H34: 07/05/2025 | I34: Email | J34: Sent | K34: =IF(J34="Won","✔","") | L34: Commercial | M34: 11663 | R34: 8/7 Follow up- Waiting on Client approval
A35: Q-25-035 | B35: 07/02/2025 | C35: Inline | D35: Twin Oaks Plaza 101 Kitchenette | E35: 07/09/2025 | F35: Bid Set | G35: Hard Bid | H35: 06/28/2025 | I35: Email | J35: Sent | K35: =IF(J35="Won","✔","") | L35: Commercial, TI | M35: 7898
A36: Q-25-036 | B36: 07/11/2025 | C36: JH Kelly | D36: OCC Microwave Shelf | E36: 07/11/2025 | F36: Email | G36: Hard Bid | H36: 07/11/2025 | I36: Email | J36: Sent | K36: =IF(J36="Won","✔","") | L36: Renovation | M36: 721.45
A37: Q-25-037 | B37: 07/08/2025 | C37: Andersen | D37: Vancouver VA Dental | E37: 07/11/2025 | F37: CD | G37: Hard Bid (Fab Only) | H37: 07/10/2025 | I37: Email | J37: Sent | K37: =IF(J37="Won","✔","") | L37: Healthcare, Dental, Renovation | M37: 7861 | N37: https://www.zztakeoff.com/app/takeoff?projectId=jmXtHDuNymN3cbeYh&pageId=i4kKnRGfeYNcBEaoG | Q37: Supply Only Bid
A38: Q-25-038 | B38: 07/10/2025 | C38: Norwest | D38: OSM Phase 2- Add Counter Storage Nook | E38: 07/15/2025 | F38: Bid Set | G38: Hard Bid | H38: 07/14/2025 | I38: Procore | J38: Won | K38: =IF(J38="Won","✔","") -> ✔ | L38: TI | M38: 1696 | S38: Yes
A39: Q-25-039 | B39: 07/15/2025 | C39: Norwest | D39: Head and Neck Lovejoy | E39: 07/15/2025 | F39: Email | G39: ROM | H39: 07/15/2025 | I39: Email | J39: Sent | K39: =IF(J39="Won","✔","") | L39: Healthcare | M39: 77128 | N39: https://www.zztakeoff.com/app/takeoff?projectId=hF8wHqMRTvXPCZCdM&pageId=Tojp3g3JEJ7aamMKc
A40: Q-25-040 | B40: 07/08/2025 | C40: R&H Construction | D40: KPFF-Vancouver TI | E40: 07/16/2025 | F40: 100% DD | G40: Hard Bid | H40: 07/15/2025 | I40: BuildingConnected | J40: Sent | K40: =IF(J40="Won","✔","") | L40: TI, Commercial | M40: 29897 | N40: https://app.buildingconnected.com/opportunities/6862f5b51391b3009e9815c0/files
...

Sheet Current Jobs
A1: Job # | B1: PM | C1: Client | D1: Project | E1: Contract ($) | F1: Appvd COs ($) | G1: Curr. Contract ($) | H1: Bid Ref | I1: Fab Status | J1: Install Date | K1: Install Status | L1: Invoice Status | M1: Notes
A2: 001 | B2: G | C2: — | D2: MT. TABOR KITCHEN | F2: =SUMIFS('Change Order'!G:G,'Change Order'!B:B,A2,'Change Order'!H:H,"Approved") -> 0 | G2: =IF(E2<>"",E2+F2,"")
A3: 002 | B3: P | C3: NIC RAMIREZ | D3: DOORS | E3: 1600 | F3: =SUMIFS('Change Order'!G:G,'Change Order'!B:B,A3,'Change Order'!H:H,"Approved") -> 0 | G3: =IF(E3<>"",E3+F3,"") -> 1600
A4: 003 | B4: G | C4: ACC / PPMC | D4: C.TOPS | E4: 5302 | F4: =SUMIFS('Change Order'!G:G,'Change Order'!B:B,A4,'Change Order'!H:H,"Approved") -> 0 | G4: =IF(E4<>"",E4+F4,"") -> 5302
A5: 004 | B5: G | C5: OHSU HMC | D5: 8 AUD C.SINKS | E5: 1100 | F5: =SUMIFS('Change Order'!G:G,'Change Order'!B:B,A5,'Change Order'!H:H,"Approved") -> 0 | G5: =IF(E5<>"",E5+F5,"") -> 1100
A6: 005 | B6: G | C6: LMHMC | D6: RADIATION ONCOLOGY REM. DRAWERS | E6: 450 | F6: =SUMIFS('Change Order'!G:G,'Change Order'!B:B,A6,'Change Order'!H:H,"Approved") -> 0 | G6: =IF(E6<>"",E6+F6,"") -> 450
A7: 006 | B7: G | C7: OHSU HMC | D7: NEW TABLETOP | E7: 643 | F7: =SUMIFS('Change Order'!G:G,'Change Order'!B:B,A7,'Change Order'!H:H,"Approved") -> 0 | G7: =IF(E7<>"",E7+F7,"") -> 643
A8: 007 | B8: G | C8: COATS & TAILS | D8: LOBBY / MISC | E8: 3920 | F8: =SUMIFS('Change Order'!G:G,'Change Order'!B:B,A8,'Change Order'!H:H,"Approved") -> 0 | G8: =IF(E8<>"",E8+F8,"") -> 3920
A9: 008 | B9: P | C9: UNIV. ACH. MILLWORK | D9: HILLS. CAMPUS | E9: 3688 | F9: =SUMIFS('Change Order'!G:G,'Change Order'!B:B,A9,'Change Order'!H:H,"Approved") -> 0 | G9: =IF(E9<>"",E9+F9,"") -> 3688
A10: 009 | B10: G | C10: OHSU HMC | D10: P/L COUNTERTOP | E10: 1180 | F10: =SUMIFS('Change Order'!G:G,'Change Order'!B:B,A10,'Change Order'!H:H,"Approved") -> 0 | G10: =IF(E10<>"",E10+F10,"") -> 1180
A11: 010 | B11: P | C11: MANION DESIGN LLC | D11: BASE CAB'S W/C | E11: 2325.2 | F11: =SUMIFS('Change Order'!G:G,'Change Order'!B:B,A11,'Change Order'!H:H,"Approved") -> 0 | G11: =IF(E11<>"",E11+F11,"") -> 2325.2
A12: 011 | B12: G | C12: VIKING | D12: LGS MOB 2 OP PHARMACY | E12: 47988 | F12: =SUMIFS('Change Order'!G:G,'Change Order'!B:B,A12,'Change Order'!H:H,"Approved") -> 0 | G12: =IF(E12<>"",E12+F12,"") -> 47988 | H12: Q-26-003
A13: 012 | B13: G | C13: NORWEST | D13: OR VASC. SPECIALISTS | E13: 55575 | F13: =SUMIFS('Change Order'!G:G,'Change Order'!B:B,A13,'Change Order'!H:H,"Approved") -> 0 | G13: =IF(E13<>"",E13+F13,"") -> 55575
A14: 013 | B14: G | C14: NORTHWEST PRIMARY CARE | D14: KITCHEN | E14: 7183 | F14: =SUMIFS('Change Order'!G:G,'Change Order'!B:B,A14,'Change Order'!H:H,"Approved") -> 0 | G14: =IF(E14<>"",E14+F14,"") -> 7183
A15: 014 | B15: J | C15: LSCMC | D15: 527 CLOSET | E15: VOID | M15: VOID - crossed out on original job list
A16: 015 | B16: G | C16: JESUIT HS | D16: CT & SHELVES | E16: 589.95 | F16: =SUMIFS('Change Order'!G:G,'Change Order'!B:B,A16,'Change Order'!H:H,"Approved") -> 0 | G16: =IF(E16<>"",E16+F16,"") -> 589.95
A17: 016 | B17: G | C17: JOHN | D17: MDF CIRCLES | F17: =SUMIFS('Change Order'!G:G,'Change Order'!B:B,A17,'Change Order'!H:H,"Approved") -> 0 | G17: =IF(E17<>"",E17+F17,"")
A18: 017 | B18: G | C18: JOHN | D18: PLYWOOD PANELS | F18: =SUMIFS('Change Order'!G:G,'Change Order'!B:B,A18,'Change Order'!H:H,"Approved") -> 0 | G18: =IF(E18<>"",E18+F18,"")
A19: 018 | B19: G | C19: LMHMC | D19: MOB 2 STE 200 | E19: 6118 | F19: =SUMIFS('Change Order'!G:G,'Change Order'!B:B,A19,'Change Order'!H:H,"Approved") -> 0 | G19: =IF(E19<>"",E19+F19,"") -> 6118
A20: 019 | B20: G | C20: OREGON RESTORATION | D20: VANITY | E20: 1074 | F20: =SUMIFS('Change Order'!G:G,'Change Order'!B:B,A20,'Change Order'!H:H,"Approved") -> 0 | G20: =IF(E20<>"",E20+F20,"") -> 1074
A21: 020 | B21: P | C21: MARK HORYAT | D21: MISC | F21: =SUMIFS('Change Order'!G:G,'Change Order'!B:B,A21,'Change Order'!H:H,"Approved") -> 0 | G21: =IF(E21<>"",E21+F21,"")
A22: 021 | B22: G | C22: NORWEST | D22: TOC LAB REMODEL | E22: 3504 | F22: =SUMIFS('Change Order'!G:G,'Change Order'!B:B,A22,'Change Order'!H:H,"Approved") -> 0 | G22: =IF(E22<>"",E22+F22,"") -> 3504
A23: 022 | B23: G | C23: 5 STAR | D23: EMANUAL RM 5400 CASEWORK | E23: 5713 | F23: =SUMIFS('Change Order'!G:G,'Change Order'!B:B,A23,'Change Order'!H:H,"Approved") -> 0 | G23: =IF(E23<>"",E23+F23,"") -> 5713
A24: 023 | B24: P | C24: JOHN HOLTMANN | D24: GOLF CABINET | F24: =SUMIFS('Change Order'!G:G,'Change Order'!B:B,A24,'Change Order'!H:H,"Approved") -> 0 | G24: =IF(E24<>"",E24+F24,"")
A25: 024 | B25: G | C25: CCDC | D25: VOLCANO VIEW BOOKCASES | E25: 4114 | F25: =SUMIFS('Change Order'!G:G,'Change Order'!B:B,A25,'Change Order'!H:H,"Approved") -> 0 | G25: =IF(E25<>"",E25+F25,"") -> 4114
A26: 025 | B26: G | C26: SCHAFFRON CONST | D26: 2 DOORS | F26: =SUMIFS('Change Order'!G:G,'Change Order'!B:B,A26,'Change Order'!H:H,"Approved") -> 0 | G26: =IF(E26<>"",E26+F26,"")
A27: 026 | B27: G | C27: ESSEX | D27: BONNEVILLE ST JOHNS | E27: 3845 | F27: =SUMIFS('Change Order'!G:G,'Change Order'!B:B,A27,'Change Order'!H:H,"Approved") -> 0 | G27: =IF(E27<>"",E27+F27,"") -> 3845
A28: 027 | B28: G | C28: LMHMC | D28: MATERNITY CAB | E28: 1973 | F28: =SUMIFS('Change Order'!G:G,'Change Order'!B:B,A28,'Change Order'!H:H,"Approved") -> 0 | G28: =IF(E28<>"",E28+F28,"") -> 1973
A29: 028 | B29: G | C29: CCDC | D29: PACIFIC BLD SUITE 1012-1015 | E29: 9296 | F29: =SUMIFS('Change Order'!G:G,'Change Order'!B:B,A29,'Change Order'!H:H,"Approved") -> 0 | G29: =IF(E29<>"",E29+F29,"") -> 9296
A30: 029 | B30: G | C30: TRAINOR COMMERCIAL CONST. | D30: DESIGN WITHIN REACH | E30: 22923 | F30: =SUMIFS('Change Order'!G:G,'Change Order'!B:B,A30,'Change Order'!H:H,"Approved") -> 0 | G30: =IF(E30<>"",E30+F30,"") -> 22923 | H30: Q-26-035
A31: 030 | B31: J | C31: R. HAKES | D31: PACIFIC OFFICE AUTOMATION RENO | E31: 6657 | F31: =SUMIFS('Change Order'!G:G,'Change Order'!B:B,A31,'Change Order'!H:H,"Approved") -> 0 | G31: =IF(E31<>"",E31+F31,"") -> 6657 | H31: Q-26-043
A32: 031 | B32: J | C32: R. HAKES | D32: ST. ANDREWS CHURCH DR | E32: 13731 | F32: =SUMIFS('Change Order'!G:G,'Change Order'!B:B,A32,'Change Order'!H:H,"Approved") -> 0 | G32: =IF(E32<>"",E32+F32,"") -> 13731
A33: 032 | B33: G | C33: LMHMC | D33: FIV CABIN | F33: =SUMIFS('Change Order'!G:G,'Change Order'!B:B,A33,'Change Order'!H:H,"Approved") -> 0 | G33: =IF(E33<>"",E33+F33,"")
A34: 033 | B34: G | C34: 5 STAR | D34: UNITY LOBBY DRAWER BOX | E34: 157.5 | F34: =SUMIFS('Change Order'!G:G,'Change Order'!B:B,A34,'Change Order'!H:H,"Approved") -> 0 | G34: =IF(E34<>"",E34+F34,"") -> 157.5
A35: 034 | B35: G | C35: INLINE | D35: OFFICE REMODEL | E35: 4955 | F35: =SUMIFS('Change Order'!G:G,'Change Order'!B:B,A35,'Change Order'!H:H,"Approved") -> 0 | G35: =IF(E35<>"",E35+F35,"") -> 4955 | H35: Q-26-086
A36: 035 | B36: G | C36: BEAVERTON DENTAL | D36: MISC | F36: =SUMIFS('Change Order'!G:G,'Change Order'!B:B,A36,'Change Order'!H:H,"Approved") -> 0 | G36: =IF(E36<>"",E36+F36,"")
A37: 036 | B37: G | C37: ACC / PROV. GATEWAY | D37: MOB X-RAY | E37: 1746 | F37: =SUMIFS('Change Order'!G:G,'Change Order'!B:B,A37,'Change Order'!H:H,"Approved") -> 0 | G37: =IF(E37<>"",E37+F37,"") -> 1746
A38: 037 | B38: G | C38: AWE | D38: CUT PARTS | E38: 200 | F38: =SUMIFS('Change Order'!G:G,'Change Order'!B:B,A38,'Change Order'!H:H,"Approved") -> 0 | G38: =IF(E38<>"",E38+F38,"") -> 200
A39: 038 | B39: G | C39: LOIS | D39: G. TOP | F39: =SUMIFS('Change Order'!G:G,'Change Order'!B:B,A39,'Change Order'!H:H,"Approved") -> 0 | G39: =IF(E39<>"",E39+F39,"")
A40: 039 | B40: G | C40: ALOFT | D40: REFINISH DOOR | F40: =SUMIFS('Change Order'!G:G,'Change Order'!B:B,A40,'Change Order'!H:H,"Approved") -> 0 | G40: =IF(E40<>"",E40+F40,"")
...

Sheet Change Order
A1: CO # | B1: Job ID | C1: Client | D1: Project Name | E1: CO Description | F1: Date Submitted | G1: Amount ($) | H1: Status | I1: Approved Date | J1: Notes
A2: CO-26-001-01 | B2: Q-26-003 | C2: Viking | D2: Legacy Good Sam Pharmacy Retrofit | E2: Owner-directed scope addition — additional upper cabs Room 112 | G2: 2400 | H2: Pending
A3: CO-26-062-01 | B3: Q-26-062 | C3: Andersen | D3: LSMC OP Pharmacy | E3: ASI-01 - Add Full Height Cab with Lock, Pick-up windown shelving | F3: 46132 | G3: 2178 | H3: Pending
A4: CO # format: CO-YY-JJJ-NN (e.g. CO-26-003-01 = 2026, Job Q-26-003, CO #1)

Sheet Historical
A1: Year | B1: Total Bids | C1: Submitted | D1: Won | E1: Win Rate | F1: Total Won Value ($) | G1: Avg Bid Value ($) | H1: Notes
A2: 2024 | E2: =IFERROR(D2/C2,0) -> 0 | F2: 1861816 | H2: Full year revenue — manually recorded
A3: 2025 | B3: =COUNTA('2025 Bid Tracker'!D:D)-COUNTIF('2025 Bid Tracker'!D:D,"Project Name")-1-COUNTIF('2025 Bid Tracker'!G:G,"Budget") -> 143 | C3: =COUNTIFS('2025 Bid Tracker'!J:J,"Sent",'2025 Bid Tracker'!G:G,"<>Budget")+COUNTIFS('2025 Bid Tracker'!J:J,"Won",'2025 Bid Tracker'!G:G,"<>Budget") -> 93 | D3: =COUNTIFS('2025 Bid Tracker'!K:K,"✔",'2025 Bid Tracker'!G:G,"<>Budget") -> 17 | E3: =IFERROR(D3/C3,0) -> 0.1827957 | F3: =SUMIFS('2025 Bid Tracker'!M:M,'2025 Bid Tracker'!K:K,"✔",'2025 Bid Tracker'!G:G,"<>Budget")-'2025 Bid Tracker'!M126-'2025 Bid Tracker'!M183-'2025 Bid Tracker'!M125-'2025 Bid Tracker'!M154 -> 331875.97 | G3: =IFERROR(F3/D3,0) -> 19522.116 | H3: 2025 partial as of 9/4/25: $1,924,157 revenue. Powells PDX, Oregon Vascular, Greenburg Pediatric moved to 2026.
A4: 2026 | B4: =COUNTA('2026 Bid Tracker'!D:D)-COUNTIF('2026 Bid Tracker'!D:D,"Project Name")-1-COUNTIF('2026 Bid Tracker'!G:G,"Budget") -> 108 | C4: =COUNTIFS('2026 Bid Tracker'!J:J,"Sent",'2026 Bid Tracker'!G:G,"<>Budget")+COUNTIFS('2026 Bid Tracker'!J:J,"Won",'2026 Bid Tracker'!G:G,"<>Budget") -> 91 | D4: =COUNTIFS('2026 Bid Tracker'!K:K,"✔",'2026 Bid Tracker'!G:G,"<>Budget") -> 24 | E4: =IFERROR(D4/C4,0) -> 0.26373626 | F4: =SUMIFS('2026 Bid Tracker'!M:M,'2026 Bid Tracker'!K:K,"✔",'2026 Bid Tracker'!G:G,"<>Budget")+'2025 Bid Tracker'!M126+'2025 Bid Tracker'!M183+'2025 Bid Tracker'!M125+'2025 Bid Tracker'!M154 -> 549952 | G4: =IFERROR(F4/D4,0) -> 22914.667 | H4: Year in progress. Includes Powells PDX, Oregon Vascular, Greenburg Pediatric, TOC Path Lab from 2025 tracker (2026 revenue).

Sheet Dashboard
A1: Estimating Dashboard — 2026 YTD vs 2025
A2: Metric | B2: 2026 (YTD) | C2: 2025 (Full Year) | D2: Notes
A3: Total Bids Logged | B3: =COUNTA('2026 Bid Tracker'!D:D)-COUNTIF('2026 Bid Tracker'!D:D,"Project Name")-1 -> 131 | C3: =COUNTA('2025 Bid Tracker'!D:D)-COUNTIF('2025 Bid Tracker'!D:D,"Project Name")-1 -> 178
A4: Bids Submitted | B4: =COUNTIF('2026 Bid Tracker'!J:J,"Sent")+COUNTIF('2026 Bid Tracker'!J:J,"Won") -> 113 | C4: =COUNTIF('2025 Bid Tracker'!J:J,"Sent")+COUNTIF('2025 Bid Tracker'!J:J,"Won") -> 115
A5: Bids Won | B5: =COUNTIF('2026 Bid Tracker'!K:K,"✔") -> 25 | C5: =COUNTIF('2025 Bid Tracker'!K:K,"✔") -> 20
A6: Win Rate | B6: =IFERROR(B5/B4,0) -> 0.22123894 | C6: =IFERROR(C5/C4,0) -> 0.17391304 | D6: Won ÷ Submitted
A7: Total Won Value ($) | B7: =SUMIF('2026 Bid Tracker'!K:K,"✔",'2026 Bid Tracker'!M:M) -> 418192 | C7: =SUMIF('2025 Bid Tracker'!K:K,"✔",'2025 Bid Tracker'!M:M) -> 695332.97
A8: Avg Won Bid Value ($) | B8: =IFERROR(B7/B5,0) -> 16727.68 | C8: =IFERROR(C7/C5,0) -> 34766.648 | D8: Won Value ÷ Won Count
A9: Avg Est. Bid Size ($) | B9: =IFERROR(AVERAGEIF('2026 Bid Tracker'!M:M,">0",'2026 Bid Tracker'!M:M),0) -> 47193.336 | C9: =IFERROR(AVERAGEIF('2025 Bid Tracker'!M:M,">0",'2025 Bid Tracker'!M:M),0) -> 62148.86 | D9: Avg across all logged bids
A10: Active Jobs (Current Jobs) | B10: =COUNTA('Current Jobs'!B:B)-1 -> 46 | D10: From Current Jobs tab
A11: Total Active Contract Value ($) | B11: =IFERROR(SUM('Current Jobs'!H:H),0) -> 0 | D11: Incl. approved COs

Sheet Running TO-DO
A1: July | L1: August Mileage
L2: 45874 | M2: 26 | N2: Miles R/T | O2: Park Towers#211
L3: 45875 | M3: 22 | N3: Miles R/T | O3: PeaceHealth
L4: 45877 | M4: 65 | N4: Miles R/T | O4: Mill Plains Zoom | P4: Willamette Falls Pediatric Unit
L10: Total Mileage | M10: 113
L11: 2025 Rate | M11: 0.7 | N11: /Mile
M13: 79.1
A16: Potential New Jobs
A17: JDL | B17: New Seasons Treatment
A18: pacific Crest | B18: Pacific Center 5TH Floor
A19: Norwest | B19: Greenburg Pediatric Dentistry
